Workbook

Sheet Transactions
A1: TransactionID | B1: MerchantID | C1: Date | D1: Hour | E1: Amount | F1: Status | G1: PaymentMethod | H1: FailureReason | I1: Market | J1: Channel
A2: TXN011486 | B2: M0039 | C2: 44927 | D2: 12 | E2: 3573.79 | F2: Success | G2: BNPL | I2: MKT001 | J2: POS
A3: TXN013285 | B3: M0048 | C3: 44927 | D3: 15 | E3: 26352.22 | F3: Success | G3: Wallet | I3: MKT004 | J3: Online
A4: TXN013170 | B4: M0020 | C4: 44927 | D4: 17 | E4: 4312.37 | F4: Success | G4: Card | I4: MKT005 | J4: Online
A5: TXN011414 | B5: M0001 | C5: 44927 | D5: 8 | E5: 14159.75 | F5: Success | G5: BNPL | I5: MKT001 | J5: POS
A6: TXN005265 | B6: M0037 | C6: 44927 | D6: 22 | E6: 3036.46 | F6: Success | G6: Bank Transfer | I6: MKT001 | J6: Online
A7: TXN001512 | B7: M0043 | C7: 44927 | D7: 17 | E7: 12792.69 | F7: Failed | G7: Card | H7: Expired Card | I7: MKT003 | J7: POS
A8: TXN002535 | B8: M0009 | C8: 44927 | D8: 17 | E8: 1450.27 | F8: Success | G8: Bank Transfer | I8: MKT001 | J8: POS
A9: TXN005609 | B9: M0003 | C9: 44927 | D9: 13 | E9: 2614.57 | F9: Success | G9: BNPL | I9: MKT003 | J9: Online
A10: TXN007942 | B10: M0001 | C10: 44927 | D10: 16 | E10: 16942.9 | F10: Success | G10: Wallet | I10: MKT001 | J10: Online
A11: TXN014975 | B11: M0044 | C11: 44927 | D11: 6 | E11: 2951.72 | F11: Failed | G11: Card | H11: Fraud Suspicion | I11: MKT001 | J11: Online
A12: TXN003442 | B12: M0004 | C12: 44927 | D12: 14 | E12: 1080.01 | F12: Success | G12: BNPL | I12: MKT002 | J12: POS
A13: TXN013319 | B13: M0011 | C13: 44927 | D13: 20 | E13: 17534.25 | F13: Success | G13: Card | I13: MKT004 | J13: Online
A14: TXN000767 | B14: M0001 | C14: 44927 | D14: 18 | E14: 26404.15 | F14: Success | G14: Wallet | I14: MKT001 | J14: POS
A15: TXN012961 | B15: M0011 | C15: 44927 | D15: 0 | E15: 19100.08 | F15: Failed | G15: BNPL | H15: Insufficient Funds | I15: MKT004 | J15: POS
A16: TXN006487 | B16: M0005 | C16: 44928 | D16: 22 | E16: 4000.31 | F16: Success | G16: Card | I16: MKT002 | J16: Online
A17: TXN009825 | B17: M0018 | C17: 44928 | D17: 14 | E17: 4668.16 | F17: Success | G17: Wallet | I17: MKT005 | J17: Online
A18: TXN013975 | B18: M0044 | C18: 44928 | D18: 18 | E18: 4522.21 | F18: Failed | G18: BNPL | H18: Invalid CVV | I18: MKT001 | J18: Online
A19: TXN003089 | B19: M0019 | C19: 44928 | D19: 15 | E19: 40484.26 | F19: Success | G19: BNPL | I19: MKT001 | J19: POS
A20: TXN001762 | B20: M0038 | C20: 44928 | D20: 19 | E20: 2451.77 | F20: Success | G20: Wallet | I20: MKT004 | J20: Online
A21: TXN008263 | B21: M0039 | C21: 44928 | D21: 18 | E21: 22821.87 | F21: Success | G21: Card | I21: MKT001 | J21: POS
A22: TXN002020 | B22: M0033 | C22: 44928 | D22: 16 | E22: 30723.04 | F22: Failed | G22: Bank Transfer | H22: Fraud Suspicion | I22: MKT002 | J22: Online
A23: TXN008171 | B23: M0032 | C23: 44928 | D23: 19 | E23: 26146.96 | F23: Success | G23: Wallet | I23: MKT003 | J23: Online
A24: TXN004509 | B24: M0032 | C24: 44928 | D24: 15 | E24: 22382.51 | F24: Success | G24: BNPL | I24: MKT003 | J24: Online
A25: TXN003589 | B25: M0022 | C25: 44928 | D25: 8 | E25: 4395.67 | F25: Success | G25: Wallet | I25: MKT005 | J25: Online
A26: TXN005099 | B26: M0015 | C26: 44928 | D26: 13 | E26: 253.46 | F26: Success | G26: Wallet | I26: MKT002 | J26: Online
A27: TXN005711 | B27: M0023 | C27: 44928 | D27: 9 | E27: 3614.12 | F27: Success | G27: Bank Transfer | I27: MKT004 | J27: POS
A28: TXN012980 | B28: M0040 | C28: 44928 | D28: 17 | E28: 11327.73 | F28: Success | G28: Wallet | I28: MKT003 | J28: Online
A29: TXN010808 | B29: M0010 | C29: 44928 | D29: 12 | E29: 849.67 | F29: Failed | G29: Wallet | H29: Expired Card | I29: MKT005 | J29: POS
A30: TXN004247 | B30: M0003 | C30: 44928 | D30: 10 | E30: 1379.14 | F30: Success | G30: Card | I30: MKT003 | J30: POS
A31: TXN010539 | B31: M0010 | C31: 44928 | D31: 15 | E31: 3592.66 | F31: Success | G31: Bank Transfer | I31: MKT005 | J31: Online
A32: TXN013529 | B32: M0030 | C32: 44928 | D32: 15 | E32: 3712.48 | F32: Failed | G32: Bank Transfer | H32: Invalid CVV | I32: MKT004 | J32: Online
A33: TXN014022 | B33: M0018 | C33: 44928 | D33: 10 | E33: 520.47 | F33: Success | G33: Bank Transfer | I33: MKT005 | J33: Online
A34: TXN011360 | B34: M0011 | C34: 44928 | D34: 15 | E34: 15327.45 | F34: Success | G34: BNPL | I34: MKT004 | J34: Online
A35: TXN003849 | B35: M0013 | C35: 44929 | D35: 17 | E35: 18709.29 | F35: Pending | G35: Wallet | I35: MKT001 | J35: POS
A36: TXN013411 | B36: M0027 | C36: 44929 | D36: 8 | E36: 866.64 | F36: Success | G36: Bank Transfer | I36: MKT003 | J36: POS
A37: TXN010576 | B37: M0033 | C37: 44929 | D37: 20 | E37: 26550.87 | F37: Success | G37: Card | I37: MKT002 | J37: Online
A38: TXN014804 | B38: M0038 | C38: 44929 | D38: 8 | E38: 4019.43 | F38: Pending | G38: Card | I38: MKT004 | J38: Online
A39: TXN005235 | B39: M0008 | C39: 44929 | D39: 14 | E39: 4253.5 | F39: Success | G39: Wallet | I39: MKT005 | J39: Online
A40: TXN006320 | B40: M0021 | C40: 44929 | D40: 6 | E40: 2647.54 | F40: Success | G40: BNPL | I40: MKT002 | J40: POS
...

Sheet Merchants
A1: MerchantID | B1: MerchantName | C1: Segment | D1: Industry | E1: Market | F1: OnboardingDate | G1: LastTransactionDate | H1: DaysSinceLastTransaction | I1: RiskFlag | J1: Merchant Tenure
A2: M0001 | B2: Cairo Bites | C2: Enterprise | D2: Retail | E2: MKT001 | F2: 45467 | G2: 45727 | H2: 20 | I2: Active | J2: =ABS(Merchants[[#This Row],[OnboardingDate]]-Merchants[[#This Row],[LastTransactionDate]]) -> 260
A3: M0002 | B3: Nile Retail | C3: Enterprise | D3: Healthcare | E3: MKT001 | F3: 45360 | G3: 45606 | H3: 141 | I3: Churned | J3: =ABS(Merchants[[#This Row],[OnboardingDate]]-Merchants[[#This Row],[LastTransactionDate]]) -> 246
A4: M0003 | B4: AlAhly Travel | C4: SME | D4: Food | E4: MKT003 | F4: 45143 | G4: 45722 | H4: 25 | I4: Active | J4: =ABS(Merchants[[#This Row],[OnboardingDate]]-Merchants[[#This Row],[LastTransactionDate]]) -> 579
A5: M0004 | B5: MedPlus Health | C5: SME | D5: Food | E5: MKT002 | F5: 45479 | G5: 45740 | H5: 7 | I5: Active | J5: =ABS(Merchants[[#This Row],[OnboardingDate]]-Merchants[[#This Row],[LastTransactionDate]]) -> 261
A6: M0005 | B6: Desert Fashion | C6: SME | D6: Food | E6: MKT002 | F6: 45132 | G6: 45670 | H6: 77 | I6: High Risk | J6: =ABS(Merchants[[#This Row],[OnboardingDate]]-Merchants[[#This Row],[LastTransactionDate]]) -> 538
A7: M0006 | B7: Karachi Kitchens | C7: SME | D7: Retail | E7: MKT002 | F7: 45246 | G7: 45734 | H7: 13 | I7: Active | J7: =ABS(Merchants[[#This Row],[OnboardingDate]]-Merchants[[#This Row],[LastTransactionDate]]) -> 488
A8: M0007 | B8: Lahore Mart | C8: Enterprise | D8: Retail | E8: MKT001 | F8: 45335 | G8: 45673 | H8: 74 | I8: High Risk | J8: =ABS(Merchants[[#This Row],[OnboardingDate]]-Merchants[[#This Row],[LastTransactionDate]]) -> 338
A9: M0008 | B9: PakAir Travels | C9: SME | D9: Healthcare | E9: MKT005 | F9: 45309 | G9: 45688 | H9: 59 | I9: At Risk | J9: =ABS(Merchants[[#This Row],[OnboardingDate]]-Merchants[[#This Row],[LastTransactionDate]]) -> 379
A10: M0009 | B10: CityHealth PK | C10: SME | D10: Food | E10: MKT001 | F10: 45375 | G10: 45554 | H10: 193 | I10: Churned | J10: =ABS(Merchants[[#This Row],[OnboardingDate]]-Merchants[[#This Row],[LastTransactionDate]]) -> 179
A11: M0010 | B11: TechStore PK | C11: SME | D11: Healthcare | E11: MKT005 | F11: 45456 | G11: 45730 | H11: 17 | I11: Active | J11: =ABS(Merchants[[#This Row],[OnboardingDate]]-Merchants[[#This Row],[LastTransactionDate]]) -> 274
A12: M0011 | B12: Nairobi Eats | C12: Enterprise | D12: Healthcare | E12: MKT004 | F12: 45389 | G12: 45574 | H12: 173 | I12: Churned | J12: =ABS(Merchants[[#This Row],[OnboardingDate]]-Merchants[[#This Row],[LastTransactionDate]]) -> 185
A13: M0012 | B13: Savanna Shop | C13: Enterprise | D13: Healthcare | E13: MKT001 | F13: 45050 | G13: 45721 | H13: 26 | I13: Active | J13: =ABS(Merchants[[#This Row],[OnboardingDate]]-Merchants[[#This Row],[LastTransactionDate]]) -> 671
... A51: M0050 | B51: BluNile Retail EG | C51: SME | D51: Travel | E51: MKT005 | F51: 44982 | G51: 45731 | H51: 16 | I51: Active | J51: =ABS(Merchants[[#This Row],[OnboardingDate]]-Merchants[[#This Row],[LastTransactionDate]]) -> 749

Sheet Markets
A1: MarketID | B1: MarketName | C1: Currency | D1: Region
A2: MKT001 | B2: Egypt | C2: EGP | D2: North Africa
A3: MKT002 | B3: Pakistan | C3: PKR | D3: South Asia
A4: MKT003 | B4: Kenya | C4: KES | D4: East Africa
A5: MKT004 | B5: UAE | C5: AED | D5: Middle East
A6: MKT005 | B6: Morocco | C6: MAD | D6: North Africa

Sheet Calendar
A1: Date | B1: Day | C1: Month | D1: MonthName | E1: Quarter | F1: Year | G1: MonthYear
A2: 44927 | B2: Sunday | C2: 1 | D2: January | E2: 1 | F2: 2023 | G2: 44927
A3: 44928 | B3: Monday | C3: 1 | D3: January | E3: 1 | F3: 2023 | G3: 44927
A4: 44929 | B4: Tuesday | C4: 1 | D4: January | E4: 1 | F4: 2023 | G4: 44927
A5: 44930 | B5: Wednesday | C5: 1 | D5: January | E5: 1 | F5: 2023 | G5: 44927
A6: 44931 | B6: Thursday | C6: 1 | D6: January | E6: 1 | F6: 2023 | G6: 44927
A7: 44932 | B7: Friday | C7: 1 | D7: January | E7: 1 | F7: 2023 | G7: 44927
A8: 44933 | B8: Saturday | C8: 1 | D8: January | E8: 1 | F8: 2023 | G8: 44927
A9: 44934 | B9: Sunday | C9: 1 | D9: January | E9: 1 | F9: 2023 | G9: 44927
A10: 44935 | B10: Monday | C10: 1 | D10: January | E10: 1 | F10: 2023 | G10: 44927
A11: 44936 | B11: Tuesday | C11: 1 | D11: January | E11: 1 | F11: 2023 | G11: 44927
A12: 44937 | B12: Wednesday | C12: 1 | D12: January | E12: 1 | F12: 2023 | G12: 44927
A13: 44938 | B13: Thursday | C13: 1 | D13: January | E13: 1 | F13: 2023 | G13: 44927
... A822: 45747 | B822: Monday | C822: 3 | D822: March | E822: 1 | F822: 2025 | G822: 45717

Sheet Measure Table - Merchants
A1: Active Merchants | B1: =COUNTIF(Merchants[RiskFlag],"Active") -> 27
A2: Merchant Churn Rate | B2: =GETPIVOTDATA("Count of MerchantID",A15,"RiskFlag","Churned") -> 0.24
A3: Avg. Days Since Last Transaction | B3: =AVERAGE(Merchants[DaysSinceLastTransaction]) -> 56.24
A4: At-Risk & High-Risk Merchants | B4: =COUNTIF(Merchants[RiskFlag],"At Risk")+COUNTIF(Merchants[RiskFlag],"High Risk")/COUNTA(Merchants[RiskFlag]) -> 6.1
A5: Average Active Merchant Tenure | B5: =AVERAGEIF(Merchants[RiskFlag],"Active",Merchants[Merchant Tenure]) -> 495.51852
A6: Top Merchant Industry | B6: =GETPIVOTDATA("Count of MerchantID",A23,"Industry","Food") -> 16
A12: RiskFLag | B12: Count of MerchantID
A13: Active | B13: 0.54
A14: At Risk | B14: 0.12
A15: Churned | B15: 0.24
A16: High Risk | B16: 0.1
A17: Grand Total | B17: 1
A19: Industry | B19: Count of MerchantID
A20: Travel | B20: 11
A21: Retail | B21: 13
A22: Healthcare | B22: 10
A23: Food | B23: 16
A24: Grand Total | B24: 50
E25: =AVERAGE(D8:D56) -> 0
A33: 1-Merchant Count by Segment
A34: Segment | B34: Count of MerchantID
A35: SME | B35: 24
A36: Enterprise | B36: 26
A37: Grand Total | B37: 50
A39: 2-Merchant RiskFlag Distribution
A40: RiskFLag | B40: Count of MerchantID
A41: Active | B41: 0.54
A42: At Risk | B42: 0.12
A43: Churned | B43: 0.24
A44: High Risk | B44: 0.1
A45: Grand Total | B45: 1
A47: 3-Merchant Count by Industry
A48: Industry | B48: Count of MerchantID
A49: Travel | B49: 11
A50: Retail | B50: 13
A51: Healthcare | B51: 10
A52: Food | B52: 16
A53: Grand Total | B53: 50
A55: 4-Average Days Since Last Transaction by RiskFlag
A56: RiskFLag | B56: Average of DaysSinceLastTransaction | D56: {=D29:D56=TODAY()-Merchants[OnboardingDate]} -> 0
...

Sheet Measure Table - Markets
A2: 1-(KPI) GMV by Market | I2: 1- | J2: Top Market by Successful GMV (EGYPT) | K2: =GETPIVOTDATA("[Measures].[Sum of Amount]",$A$5,"[Markets].[MarketName]","[Markets].[MarketName].&[Egypt]") -> 1.009787e+08
A3: Status | B3: Success | I3: 2- | J3: Top Market Success Rate | K3: =AVERAGE(D16:D20) -> 0.86685851
I4: 3- | J4: Merchant Count–GMV Correlation | K4: =CORREL(B27:B31,C27:C31) -> 0.93051858
A5: Row Labels | B5: Sum of Amount | I5: 4- | J5: Highest Avg. Transaction Value (EGYPT) | K5: =GETPIVOTDATA("[Measures].[Average of Amount]",$A$37,"[Markets].[MarketName]","[Markets].[MarketName].&[Egypt]") -> 25642.127
A6: Egypt | B6: 1.009787e+08 | I6: 5- | J6: Highest Market Failure Rate Kenya — Card Declined | K6: =GETPIVOTDATA("[Measures].[Count of TransactionID]",$A$51,"[Markets].[MarketName]","[Markets].[MarketName].&[Kenya]","[Transactions].[Status]","[Transactions].[Status].&[Failed]") -> 0.087354409
A7: Kenya | B7: 36137433 | I7: 6- | J7: Largest Market GMV Share (EGYPT) | K7: =GETPIVOTDATA("[__Xl2].[Measures].[Sum of Amount]",$A$77,"[Markets].[MarketName]","[Markets].[MarketName].&[Egypt]") -> 0.43217214
A8: Morocco | B8: 31133084
A9: Pakistan | B9: 38086554
A10: UAE | B10: 26807395
A11: Grand Total | B11: 2.3314316e+08
A13: 2-(KPI) Success Rate by Market
A14: Count of TransactionID | B14: Column Labels
A15: Row Labels | B15: Failed | C15: Pending | D15: Success | E15: Grand Total
A16: Egypt | B16: 0.083609821 | C16: 0.04534395 | D16: 0.87104623 | E16: 1
A17: Kenya | B17: 0.087354409 | C17: 0.046589018 | D17: 0.86605657 | E17: 1
A18: Morocco | B18: 0.081298093 | C18: 0.049514888 | D18: 0.86918702 | E18: 1
A19: Pakistan | B19: 0.085517693 | C19: 0.05078637 | D19: 0.86369594 | E19: 1
A20: UAE | B20: 0.084562439 | C20: 0.051130777 | D20: 0.86430678 | E20: 1
A21: Grand Total | B21: 0.084266667 | C21: 0.048266667 | D21: 0.86746667 | E21: 1
A23: 3-(KPI) Merchant Count vs GMV by Market
A24: Status | B24: Success
A26: Row Labels | B26: Distinct Count of MerchantID | C26: Sum of Amount
A27: Egypt | B27: 15 | C27: 1.009787e+08
A28: Kenya | B28: 8 | C28: 36137433
A29: Morocco | B29: 10 | C29: 31133084
A30: Pakistan | B30: 10 | C30: 38086554
A31: UAE | B31: 7 | C31: 26807395
A32: Grand Total | B32: 50 | C32: 2.3314316e+08
A34: 4-(KPI) Merchant Count vs GMV by Market
A35: Status | B35: Success
A37: Row Labels | B37: Average of Amount
A38: Egypt | B38: 25642.127
A39: Kenya | B39: 17357.077
A40: Morocco | B40: 11983.481
A41: Pakistan | B41: 14448.617
A42: UAE | B42: 15248.803
A43: Grand Total | B43: 17917.55
A50: 5-Part1 (KPI) Failure Rate by Market
A51: Count of TransactionID | B51: Column Labels
A52: Row Labels | B52: Failed | C52: Pending | D52: Success | E52: Grand Total
...

Sheet Measure Table - Calendar
A1: 1-(KPI) MoM GMV Growth by Month
A3: Status | B3: Success | I3: 1Kpi Latest MoM GMV Growth | J3: {=A11:C11} -> Mar | K3: 11792184 | L3: 0.038791197
I4: 2 KPI Peak Transaction Hour | J4: {=A45:B45} -> 9 | K4: 1092
A5: MonthYear | B5: GMV | C5: MoM Growth % | I5: 3 KPI Dominant Transaction Channel | J5: {=A50:B50} -> Online | K5: 0.50066667
A6: 2023 | B6: 88715050 | C6: #N/A | I6: 4 KPI Channel Avg. Transaction Value Gap | J6: =B57-B58 -> 68.181263
A7: 2024 | B7: 1.1086758e+08 | C7: #N/A | I7: 5 KPI Strongest Quarter (Q1) | J7: =GETPIVOTDATA("[Measures].[Sum of Amount]",$A$62,"[Calendar].[Quarter]","[Calendar].[Quarter].&[1]") -> 94053253
A8: 2025 | I8: 6 KPI Latest YoY GMV Growth | J8: {=A72:C73} -> January | K8: 12533848 | L8: -0.0044617778
A9: Jan | B9: 10416513 | J9: March | K9: 13372386 | L9: 0.066901903
A10: Feb | B10: 11351833 | C10: 0.089792045
A11: Mar | B11: 11792184 | C11: 0.038791197
A12: Grand Total | B12: 2.3314316e+08
A20: 2-(KPI) Transaction Volume by Hour
A21: Hour | B21: Transaction Volume
A22: 3 | B22: 34
A23: 1 | B23: 41
A24: 2 | B24: 44
A25: 4 | B25: 45
A26: 0 | B26: 62
A27: 5 | B27: 158
A28: 23 | B28: 290
A29: 6 | B29: 304
A30: 22 | B30: 455
A31: 21 | B31: 607
A32: 7 | B32: 630
A33: 20 | B33: 675
... A45: 9 | B45: 1092
A46: Grand Total | B46: 15000
A48: 3-(KPI) Transaction Share by Channel
A49: Channel | B49: of Transactions %
A50: Online | B50: 0.50066667
A51: POS | B51: 0.49933333
A52: Grand Total | B52: 1
A55: 4-(KPI) Average Transaction Value by Channel
A56: Channel | B56: Average Transaction Value
A57: Online | B57: 18024.656
A58: POS | B58: 17956.475
A59: Grand Total | B59: 17990.611
A61: 5-(KPI) GMV by Quarter
A62: Quarter | B62: GMV
A63: 1 | B63: 94053253
...

Sheet Measure Table - Transaction
A1: Successful GMV | B1: =SUMIF(Transactions!F2:F15001,"Success",Transactions!E2:E15001) -> 2.3314316e+08 | E1: Failure Reason | F1: Count Formula
A2: Transaction Success Rate | B2: =COUNTIF(Transactions!F5:F15004,"Success")/COUNTA(Transactions!F5:F15004) -> 0.86744015 | E2: Card Declined | F2: =COUNTIF(Transactions!H2:H15001,"Card Declined") -> 190
A3: Failed Transactions | B3: =COUNTIF(Transactions!F2:F15001,"Failed") -> 1264 | E3: Insufficient Funds | F3: =COUNTIFS(Transactions!$H$2:$H$15001,H3) -> 0
A4: Avg. Successful Transaction Value | B4: =AVERAGEIF(Transactions!F2:F15001,"Success",Transactions!E2:E15001) -> 17917.55 | E4: Network Timeout | F4: =COUNTIFS(Transactions!$H$2:$H$15001,H4) -> 0
A5: Top Failure Reason | B5: =INDEX(E1:E8, MATCH(MAX(F1:F8), F1:F8, 0)) -> Card Declined | E5: Expired Card | F5: =COUNTIFS(Transactions!$H$2:$H$15001,H5) -> 0
A6: Pending Transaction Rate | B6: =GETPIVOTDATA("Status",$A$36,"Status","Pending")/GETPIVOTDATA("Status",$A$36) -> 0.048266667 | E6: Limit Exceeded | F6: =COUNTIFS(Transactions!$H$2:$H$15001,H6) -> 0 | K6: =COUNTIF(Transactions!F2:F15001,"Success")/COUNTA(Transactions!F2:F15001) -> 0.86746667
E7: Fraud Suspicion | F7: =COUNTIFS(Transactions!$H$2:$H$15001,H7) -> 0
E8: Invalid CVV | F8: =COUNTIFS(Transactions!$H$2:$H$15001,H8) -> 0
A23: Row Labels | B23: Count of FailureReason
A24: Card Declined | B24: 190
A25: Expired Card | B25: 185
A26: Fraud Suspicion | B26: 170
A27: Insufficient Funds | B27: 188
A28: Invalid CVV | B28: 161
A29: Limit Exceeded | B29: 184
A30: Network Timeout | B30: 186
A31: (blank)
A32: Grand Total | B32: 1264
A34: Status | B34: Count of Status
A35: Failed | B35: 0.084266667
A36: Pending | B36: 0.048266667
A37: Success | B37: 0.86746667
A38: Grand Total | B38: 1
A40: 1-GMV Growth Over Time
A41: Row Labels | B41: Sum of Amount
A42: 2023 | B42: 1.0252974e+08
A43: 2024 | B43: 1.2883316e+08
A44: 2025 | B44: 38496256
A45: Grand Total | B45: 2.6985916e+08
A49: 2-Success Rate by Payment Method
A50: Count of TransactionID | B50: Column Labels
A51: Row Labels | B51: Success | C51: Grand Total
A52: Bank Transfer | B52: 0.25376575 | C52: 0.25376575
A53: BNPL | B53: 0.22901937 | C53: 0.22901937
A54: Card | B54: 0.25322779 | C54: 0.25322779
A55: Wallet | B55: 0.26398709 | C55: 0.26398709
A56: Grand Total | B56: 1 | C56: 1
A59: Row Labels | B59: Sum of Amount
A60: MKT005 | B60: 0.12993941
A61: MKT004 | B61: 0.11685272
...

Sheet DashBoard - Merchants  
A1: Paymob | C1: Merchants Performance Dashboard
C5: Active Merchants | H5: Merchant Churn Rate | M5: Avg. Days Since Last Transaction
C7: =COUNTIF(Merchants[RiskFlag],"Active") -> 27 | H7: ='Measure Table - Merchants'!B2 -> 0.24 | M7: =AVERAGE(Merchants[DaysSinceLastTransaction]) -> 56.24
C11: At-Risk & High-Risk Merchants | H11: Average Active Merchant Tenure | M11: Top Merchant Industry
C13: ='Measure Table - Merchants'!B4 -> 6.1 | H13: =AVERAGEIF(Merchants[RiskFlag],"Active",Merchants[Merchant Tenure]) -> 495.51852 | M13: ='Measure Table - Merchants'!B6 -> 16

Sheet DashBoard - Markets 
A1: Paymob | C1: Markets Performance Dashboard
C5: Top Market by Successful GMV (EGYPT) | H5: Top Market Success Rate | M5: Merchant Count–GMV Correlation
C7: ='Measure Table - Markets'!K2 -> 1.009787e+08 | H7: ='Measure Table - Markets'!K3 -> 0.86685851 | M7: ='Measure Table - Markets'!K4 -> 0.93051858
C11: Highest Avg. Transaction Value (EGYPT) | H11: Highest Market Failure Rate (Kenya) | M11: Largest Market GMV Share (EGYPT)
C13: ='Measure Table - Markets'!K5 -> 25642.127 | H13: ='Measure Table - Markets'!K6 -> 0.087354409 | M13: ='Measure Table - Markets'!K7 -> 0.43217214

Sheet DashBoard - Calendar
A1: Paymob | C1: Calendar Performance Dashboard
C5: Latest MoM Growth (MARCH) | H5: Peak Transaction Hour | M5: KPI Dominant Transaction Channel (Online)
C7: ='Measure Table - Calendar'!L3 -> 0.038791197 | H7: ='Measure Table - Calendar'!K4 -> 1092 | M7: ='Measure Table - Calendar'!K5 -> 0.50066667
C11: Channel Avg. Transaction Value Gap | H11: Strongest Quarter (Q1) | M11: Latest YoY Growth (MARCH)
C13: ='Measure Table - Calendar'!J6 -> 68.181263 | H13: ='Measure Table - Calendar'!J7 -> 94053253 | M13: ='Measure Table - Calendar'!L9 -> 0.066901903

Sheet DashBoard - Transaction 
A1: Paymob | C1: Transaction Performance Dashboard
C5: Successful GMV | H5: Transaction Success Rate | M5: Failed Transactions
C7: =SUMIF(Transactions!F2:F15001,"Success",Transactions!E2:E15001) -> 2.3314316e+08 | H7: =COUNTIF(Transactions!F5:F15004,"Success")/COUNTA(Transactions!F5:F15004) -> 0.86744015 | M7: =COUNTIF(Transactions!F2:F15001,"Failed") -> 1264
C11: Top Failure Reason | H11: Pending Transaction Rate | M11: Avg. Successful Transaction Value
C13: ='Measure Table - Transaction'!B5 -> Card Declined | H13: ='Measure Table - Transaction'!B6 -> 0.048266667 | M13: ='Measure Table - Transaction'!B4 -> 17917.55
